Workbook
Name ALT: модель!$K$1
Name AST: модель!$K$2
Name closed: модель!$C$3
Name E1F: модель!$N$3
Name E2F: модель!$N$4
Name E3F: модель!$N$5
Name IAT: модель!$B$9:$D$12
Name MXQ: модель!$K$3
Name NLC: модель!$M$1
Name renegat: модель!$E$3
Name RUNC: эксперимент!$C$2
Name ST: модель!$G$9:$I$11
Name start: модель!$A$3

Sheet инструкция
A1: 1. | B1: Ввести заголовок в ячейку В1
B2: Табличная модель системы массового обслуживания с 3 серверами и ограничением времени ожидания
A3: 2. | B3: Ввести табличку начальных данных в ячейки А2..F3
A4: Начало | C4: Конец | E4: Уйти если ожидание больше | I4: Формат данных в ячейках start, closed -
A5: 0.375 | C5: 0.45833333 | E5: 2 | F5: мин | I5: ч:мм | J5: - модуль значений меньше 0
A6: start | C6: closed | E6: renegat | G6: <--- задайте эти имена подкрашенным зеленым ячейкам
B7: используемые аббревиатуры: | F7: SST | G7: время начала обслуживания
B8: ST | C8: время обслуживания | F8: TIQ | G8: время ожидания в очереди
B9: IAT | C9: время между прибытиями | F9: TIS | G9: время пребывания в системе
A10: 3. | B10: Ввести табличку значений в ячейки A6…D12. Задать диапазону B9:D12 имя IAT.
A11: вероят ность | B11: нижняя | C11: верхняя | D11: интервал
B12: граница | C12: граница | D12: прихода
D13: (мин)
A14: 0.45 | B14: 0 | C14: =B14+A14 -> 0.45 | D14: 1
A15: 0.25 | B15: =C14 -> 0.45 | C15: =B15+A15 -> 0.7 | D15: 3
A16: 0.1 | B16: =C15 -> 0.7 | C16: =B16+A16 -> 0.8 | D16: 5
A17: 0.2 | B17: =C16 -> 0.8 | C17: =B17+A17 -> 1 | D17: 10
A18: 4. | B18: Ввести табличку значений в ячейки F6…I11. Задать диапазону G9:I11 имя ST.
A19: вероят ность | B19: нижняя | C19: верхняя | D19: интервал
B20: граница | C20: граница | D20: сервиса
D21: (мин)
A22: 0.3 | B22: 0 | C22: =B22+A22 -> 0.3 | D22: 3
A23: 0.35 | B23: =C22 -> 0.3 | C23: =B23+A23 -> 0.65 | D23: 7
A24: 0.35 | B24: =C23 -> 0.65 | C24: =B24+A24 -> 1 | D24: 8
A25: 5. | B25: Ввести заголовок таблицы с ячейки А14
B26: время | D26: время обс- | F26: момент | G26: прогноз | I26: время | J26: прогноз 1 | K26: прогноз 2 | L26: прогноз 3 | M26: факт. | X26: время | Y26: итог. | Z26: длина
A27: клиент | B27: прихода | C27: интервал | D27: луживания | E27: интервал | F27: времени | G27: времени | H27: отка-- | I27: ухода из | J27: начала обс- | K27: начала обс- | L27: начала обс- | M27: время | N27: номер | O27: сервер 1 факт | Q27: сервер 2 факт | S27: сервер 3 факт | U27: время в | V27: время в | W27: длит-ть | X27: обслуж- | Y27: время | Z27: очереди
A28: № | B28: клиента | C28: между | D28: на сервере | E28: обслуж- | F28: прихода | G28: ожидания | H28: зался | I28: очереди | J28: луживания | K28: луживания | L28: луживания | M28: начала | N28: сервера | O28: нач | P28: кон | Q28: нач | R28: кон | S28: нач | T28: кон | U28: очереди | V28: сервере | W28: пребыв | X28: ивания | Y28: ухода | Z28: к началу
B29: (мин) | C29: клиентами | D29: (мин) | E29: ивания | F29: (ч:мин) | G29: (ч:мин) | H29: ждать ? | I29: (ч:мин) | J29: (ч:мин) | K29: (ч:мин) | L29: (ч:мин) | M29: (ч:мин) | O29: (ч:мин) | P29: (ч:мин) | Q29: (ч:мин) | R29: (ч:мин) | S29: (ч:мин) | T29: (ч:мин) | U29: (ч:мин) | V29: (ч:мин) | W29: (ч:мин) | X29: (с отказ) | Z29: обслуж.
A30: 6. | B30: В столбце А укажем номера моделируемых клиентов с 1 до 40 (но с учетом времени работы системы!)
B31: В ячейку А20 ввести формулу начала функции счетчика
B32: .=ЕСЛИ(ЕТЕКСТ(F20);"закрыто";1)
B33: В ячейку А21 ввести формулу функции счетчика с учетом завершения и скопировать ее до ячейки А59
B34: .=ЕСЛИ(ЕТЕКСТ(F21);"закрыто";A20+1)
A35: 7. | B35: В ячейки В20:В59 ввести формулу выборки значения из диапазона IAT
B36: .=ВПР(СЛЧИС();IAT;3)
A37: 8. | B37: В ячейку С20 ввести формулу перевода в минуты и скопировать ее в ячейки С21:С59
B38: .=B20/1440
A39: 9. | B39: В ячейки D20:D59 ввести формулу выборки значения из диапазона ST
B40: .=ВПР(СЛЧИС();ST;3)
...

Sheet модель
B1: Табличная модель системы массового обслуживания с 3 серверами и ограничением времени ожидания | J1: Среднее время пребывания в системе | K1: =SUM(W20:W119)/MAX(A20:A119) -> 0.004375 | L1: Количество потерянных клиентов | M1: =COUNTIF(H20:H119,"Ушел") -> 6
A2: Начало | C2: Конец | E2: Уйти если ожидание больше (мин) | J2: Среднее время обслуживания | K2: =SUMIF(N20:N119,">0",X20:X119)/MAX(A20:A119) -> 0.0042916667 | L2: Доля потерянных клиентов | M2: =COUNTIF(H20:H119,"ушел")/MAX(A20:A119) -> 0.06
A3: 0.375 | C3: 0.75 | E3: 2 | J3: Макисмальная длина очереди | K3: =MAX(Z20:Z119) -> 0 | L3: Количество заявок к 1 | M3: =SUMIF(N20:N119,1,X20:X119)/(closed-start) -> 0.48888889 | N3: =100%-M3 -> 0.51111111
L4: Количество заявок к 2 | M4: =SUMIF(N20:N119,2,X20:X119)/(closed-start) -> 0.41111111 | N4: =100%-M4 -> 0.58888889
L5: Количество заявок к 3 | M5: =SUMIF(N20:N119,3,X20:X119)/(closed-start) -> 0.24444444 | N5: =100%-M5 -> 0.75555556
A6: Вероятность | B6: Нижняя граница | C6: Верхняя граница | D6: Интервал прихода (мин) | F6: Вероятность | G6: Нижняя граница | H6: Верхняя граница | I6: Интервал сервиса (мин)
A9: 0.45 | B9: 0 | C9: =B9+A9 -> 0.45 | D9: 1 | F9: 0.3 | G9: 0 | H9: =G9+F9 -> 0.3 | I9: 3
A10: 0.25 | B10: =C9 -> 0.45 | C10: =B10+A10 -> 0.7 | D10: 3 | F10: 0.35 | G10: =H9 -> 0.3 | H10: =G10+F10 -> 0.65 | I10: 7
A11: 0.1 | B11: =C10 -> 0.7 | C11: =B11+A11 -> 0.8 | D11: 5 | F11: 0.35 | G11: =H10 -> 0.65 | H11: =G11+F11 -> 1 | I11: 8
A12: 0.2 | B12: =C11 -> 0.8 | C12: =B12+A12 -> 1 | D12: 10
A14: Клиент № | B14: Время прихода клиента (мин) | C14: Интервал между клиентами | D14: Время обслуживания на сервере (мин) | E14: Интервал обслуживания | F14: Момент времени прихода (ч:мин) | G14: Прогноз времени ожидания (ч:мин) | H14: Отказался ждать | I14: Время ухода из очереди (ч:мин) | J14: Прогноз 1 Начала обслуживания (ч:мин) | K14: Прогноз 2 Начала обслуживания (ч:мин) | L14: Прогноз 3 Начала обслуживания (ч:мин) | M14: Фактическое время начала (ч:мин) | N14: Номер сервера | O14: Сервер 1 факт | Q14: Сервер 2 факт | S14: Сервер 3 факт | U14: Время в очереди (ч:мин) | V14: Время в сервере (ч:мин) | W14: Длительность пребыв (ч:мин) | X14: Время обслуживания (с отказ) | Y14: Итоговое время ухода | Z14: Длина очереди к началу обслуживания
O16: Начало (ч:мин) | P16: Конец (ч:мин) | Q16: Начало (ч:мин) | R16: Конец (ч:мин) | S16: Начало (ч:мин) | T16: Конец (ч:мин)
F19: =start -> 0.375 | M19: =start -> 0.375 | P19: =start -> 0.375 | R19: =start -> 0.375 | T19: =start -> 0.375
A20: =IF(ISTEXT(F20),"",1) -> 1 | B20: =VLOOKUP(RAND(),IAT,3) -> 1 | C20: =B20/1440 -> 0.00069444444 | D20: =VLOOKUP(RAND(),ST,3) -> 3 | E20: =D20/1440 -> 0.0020833333 | F20: =IF(ISTEXT(F19),"",IF(F19+C20>=closed,"Закрыто",F19+C20)) -> 0.37569444 | G20: =IF(ISTEXT(F20),"",M20-F20) -> 0 | H20: =IF(ISTEXT(F20),"",IF(G20>(renegat/1440),"Ушел","")) | I20: =IF(H20="Ушел",F20+(renegat/1440),"") | J20: =MAX(P19,$F20) -> 0.37569444 | K20: =MAX(R19,$F20) -> 0.37569444 | L20: =MAX(T19,$F20) -> 0.37569444 | M20: =IF(ISTEXT(F20),"",MIN(J20:L20)) -> 0.37569444 | N20: =IF(OR(ISTEXT(F20),H20="Ушел"),"",MATCH(M20,J20:L20,0)) -> 1 | O20: =IF($N20=1,M20,"") -> 0.37569444 | P20: =IF($N20=1,O20+$E20,P19) -> 0.37777778 | Q20: =IF($N20=2,M20,"") | R20: =IF($N20=2,Q20+$E20,R19) -> 0.375 | S20: =IF($N20=3,M20,"") | T20: =IF($N20=3,S20+$E20,T19) -> 0.375 | U20: =IF(H20="Ушел",I20-F20,G20) -> 0 | V20: =IF(OR(H20="Ушел",A20="Закрыто"),"",E20) -> 0.0020833333 | W20: =IFERROR(Y20-F20,"") -> 0.0020833333 | X20: =IFERROR(IF(H20="Ушел",W20,$E20+G20),"") -> 0.0020833333 | Y20: =IFERROR(IF(H20="Ушел",I20,CHOOSE(N20,P20,R20,T20)),"") -> 0.37777778 | Z20: =COUNTIF($M$19:$M$19,">"&$F20) -> 0
A21: =IF(ISTEXT(F21),"Закрыто",A20+1) -> 2 | B21: =VLOOKUP(RAND(),IAT,3) -> 5 | C21: =B21/1440 -> 0.0034722222 | D21: =VLOOKUP(RAND(),ST,3) -> 3 | E21: =D21/1440 -> 0.0020833333 | F21: =IF(ISTEXT(F20),"",IF(F20+C21>=closed,"Закрыто",F20+C21)) -> 0.37916667 | G21: =IF(ISTEXT(F21),"",M21-F21) -> 0 | H21: =IF(ISTEXT(F21),"",IF(G21>(renegat/1440),"Ушел","")) | I21: =IF(H21="Ушел",F21+(renegat/1440),"") | J21: =IF(ISTEXT($F21),"",MAX($P$19:P20,$F21)) -> 0.37916667 | K21: =IF(ISTEXT($F21),"",MAX($R$19:R20,$F21)) -> 0.37916667 | L21: =IF(ISTEXT($F21),"",MAX(T19:T20,$F21)) -> 0.37916667 | M21: =IF(ISTEXT(F21),"",MIN(J21:L21)) -> 0.37916667 | N21: =IF(OR(ISTEXT(F21),H21="Ушел"),"",MATCH(M21,J21:L21,0)) -> 1 | O21: =IF($N21=1,M21,"") -> 0.37916667 | P21: =IF($N21=1,O21+$E21,P20) -> 0.38125 | Q21: =IF($N21=2,M21,"") | R21: =IF($N21=2,Q21+$E21,R20) -> 0.375 | S21: =IF($N21=3,M21,"") | T21: =IF($N21=3,S21+$E21,T20) -> 0.375 | U21: =IF(H21="Ушел",I21-F21,G21) -> 0 | V21: =IF(OR(H21="Ушел",A21="Закрыто"),"",E21) -> 0.0020833333 | W21: =IFERROR(Y21-F21,"") -> 0.0020833333 | X21: =IFERROR(IF(H21="Ушел",W21,$E21+G21),"") -> 0.0020833333 | Y21: =IFERROR(IF(H21="Ушел",I21,CHOOSE(N21,P21,R21,T21)),"") -> 0.38125 | Z21: =COUNTIF($M$19:$M$19,">"&$F21) -> 0
A22: =IF(ISTEXT(F22),"Закрыто",A21+1) -> 3 | B22: =VLOOKUP(RAND(),IAT,3) -> 5 | C22: =B22/1440 -> 0.0034722222 | D22: =VLOOKUP(RAND(),ST,3) -> 8 | E22: =D22/1440 -> 0.0055555556 | F22: =IF(ISTEXT(F21),"",IF(F21+C22>=closed,"Закрыто",F21+C22)) -> 0.38263889 | G22: =IF(ISTEXT(F22),"",M22-F22) -> 0 | H22: =IF(ISTEXT(F22),"",IF(G22>(renegat/1440),"Ушел","")) | I22: =IF(H22="Ушел",F22+(renegat/1440),"") | J22: =IF(ISTEXT($F22),"",MAX($P$19:P21,$F22)) -> 0.38263889 | K22: =IF(ISTEXT($F22),"",MAX($R$19:R21,$F22)) -> 0.38263889 | L22: =IF(ISTEXT($F22),"",MAX(T20:T21,$F22)) -> 0.38263889 | M22: =IF(ISTEXT(F22),"",MIN(J22:L22)) -> 0.38263889 | N22: =IF(OR(ISTEXT(F22),H22="Ушел"),"",MATCH(M22,J22:L22,0)) -> 1 | O22: =IF($N22=1,M22,"") -> 0.38263889 | P22: =IF($N22=1,O22+$E22,P21) -> 0.38819444 | Q22: =IF($N22=2,M22,"") | R22: =IF($N22=2,Q22+$E22,R21) -> 0.375 | S22: =IF($N22=3,M22,"") | T22: =IF($N22=3,S22+$E22,T21) -> 0.375 | U22: =IF(H22="Ушел",I22-F22,G22) -> 0 | V22: =IF(OR(H22="Ушел",A22="Закрыто"),"",E22) -> 0.0055555556 | W22: =IFERROR(Y22-F22,"") -> 0.0055555556 | X22: =IFERROR(IF(H22="Ушел",W22,$E22+G22),"") -> 0.0055555556 | Y22: =IFERROR(IF(H22="Ушел",I22,CHOOSE(N22,P22,R22,T22)),"") -> 0.38819444 | Z22: =COUNTIF($M$19:$M$19,">"&$F22) -> 0
A23: =IF(ISTEXT(F23),"Закрыто",A22+1) -> 4 | B23: =VLOOKUP(RAND(),IAT,3) -> 5 | C23: =B23/1440 -> 0.0034722222 | D23: =VLOOKUP(RAND(),ST,3) -> 3 | E23: =D23/1440 -> 0.0020833333 | F23: =IF(ISTEXT(F22),"",IF(F22+C23>=closed,"Закрыто",F22+C23)) -> 0.38611111 | G23: =IF(ISTEXT(F23),"",M23-F23) -> 0 | H23: =IF(ISTEXT(F23),"",IF(G23>(renegat/1440),"Ушел","")) | I23: =IF(H23="Ушел",F23+(renegat/1440),"") | J23: =IF(ISTEXT($F23),"",MAX($P$19:P22,$F23)) -> 0.38819444 | K23: =IF(ISTEXT($F23),"",MAX($R$19:R22,$F23)) -> 0.38611111 | L23: =IF(ISTEXT($F23),"",MAX(T21:T22,$F23)) -> 0.38611111 | M23: =IF(ISTEXT(F23),"",MIN(J23:L23)) -> 0.38611111 | N23: =IF(OR(ISTEXT(F23),H23="Ушел"),"",MATCH(M23,J23:L23,0)) -> 2 | O23: =IF($N23=1,M23,"") | P23: =IF($N23=1,O23+$E23,P22) -> 0.38819444 | Q23: =IF($N23=2,M23,"") -> 0.38611111 | R23: =IF($N23=2,Q23+$E23,R22) -> 0.38819444 | S23: =IF($N23=3,M23,"") | T23: =IF($N23=3,S23+$E23,T22) -> 0.375 | U23: =IF(H23="Ушел",I23-F23,G23) -> 0 | V23: =IF(OR(H23="Ушел",A23="Закрыто"),"",E23) -> 0.0020833333 | W23: =IFERROR(Y23-F23,"") -> 0.0020833333 | X23: =IFERROR(IF(H23="Ушел",W23,$E23+G23),"") -> 0.0020833333 | Y23: =IFERROR(IF(H23="Ушел",I23,CHOOSE(N23,P23,R23,T23)),"") -> 0.38819444 | Z23: =COUNTIF($M$19:$M$19,">"&$F23) -> 0
A24: =IF(ISTEXT(F24),"Закрыто",A23+1) -> 5 | B24: =VLOOKUP(RAND(),IAT,3) -> 5 | C24: =B24/1440 -> 0.0034722222 | D24: =VLOOKUP(RAND(),ST,3) -> 8 | E24: =D24/1440 -> 0.0055555556 | F24: =IF(ISTEXT(F23),"",IF(F23+C24>=closed,"Закрыто",F23+C24)) -> 0.38958333 | G24: =IF(ISTEXT(F24),"",M24-F24) -> 0 | H24: =IF(ISTEXT(F24),"",IF(G24>(renegat/1440),"Ушел","")) | I24: =IF(H24="Ушел",F24+(renegat/1440),"") | J24: =IF(ISTEXT($F24),"",MAX($P$19:P23,$F24)) -> 0.38958333 | K24: =IF(ISTEXT($F24),"",MAX($R$19:R23,$F24)) -> 0.38958333 | L24: =IF(ISTEXT($F24),"",MAX(T22:T23,$F24)) -> 0.38958333 | M24: =IF(ISTEXT(F24),"",MIN(J24:L24)) -> 0.38958333 | N24: =IF(OR(ISTEXT(F24),H24="Ушел"),"",MATCH(M24,J24:L24,0)) -> 1 | O24: =IF($N24=1,M24,"") -> 0.38958333 | P24: =IF($N24=1,O24+$E24,P23) -> 0.39513889 | Q24: =IF($N24=2,M24,"") | R24: =IF($N24=2,Q24+$E24,R23) -> 0.38819444 | S24: =IF($N24=3,M24,"") | T24: =IF($N24=3,S24+$E24,T23) -> 0.375 | U24: =IF(H24="Ушел",I24-F24,G24) -> 0 | V24: =IF(OR(H24="Ушел",A24="Закрыто"),"",E24) -> 0.0055555556 | W24: =IFERROR(Y24-F24,"") -> 0.0055555556 | X24: =IFERROR(IF(H24="Ушел",W24,$E24+G24),"") -> 0.0055555556 | Y24: =IFERROR(IF(H24="Ушел",I24,CHOOSE(N24,P24,R24,T24)),"") -> 0.39513889 | Z24: =COUNTIF($M$19:$M$19,">"&$F24) -> 0
A25: =IF(ISTEXT(F25),"Закрыто",A24+1) -> 6 | B25: =VLOOKUP(RAND(),IAT,3) -> 1 | C25: =B25/1440 -> 0.00069444444 | D25: =VLOOKUP(RAND(),ST,3) -> 8 | E25: =D25/1440 -> 0.0055555556 | F25: =IF(ISTEXT(F24),"",IF(F24+C25>=closed,"Закрыто",F24+C25)) -> 0.39027778 | G25: =IF(ISTEXT(F25),"",M25-F25) -> 0 | H25: =IF(ISTEXT(F25),"",IF(G25>(renegat/1440),"Ушел","")) | I25: =IF(H25="Ушел",F25+(renegat/1440),"") | J25: =IF(ISTEXT($F25),"",MAX($P$19:P24,$F25)) -> 0.39513889 | K25: =IF(ISTEXT($F25),"",MAX($R$19:R24,$F25)) -> 0.39027778 | L25: =IF(ISTEXT($F25),"",MAX(T23:T24,$F25)) -> 0.39027778 | M25: =IF(ISTEXT(F25),"",MIN(J25:L25)) -> 0.39027778 | N25: =IF(OR(ISTEXT(F25),H25="Ушел"),"",MATCH(M25,J25:L25,0)) -> 2 | O25: =IF($N25=1,M25,"") | P25: =IF($N25=1,O25+$E25,P24) -> 0.39513889 | Q25: =IF($N25=2,M25,"") -> 0.39027778 | R25: =IF($N25=2,Q25+$E25,R24) -> 0.39583333 | S25: =IF($N25=3,M25,"") | T25: =IF($N25=3,S25+$E25,T24) -> 0.375 | U25: =IF(H25="Ушел",I25-F25,G25) -> 0 | V25: =IF(OR(H25="Ушел",A25="Закрыто"),"",E25) -> 0.0055555556 | W25: =IFERROR(Y25-F25,"") -> 0.0055555556 | X25: =IFERROR(IF(H25="Ушел",W25,$E25+G25),"") -> 0.0055555556 | Y25: =IFERROR(IF(H25="Ушел",I25,CHOOSE(N25,P25,R25,T25)),"") -> 0.39583333 | Z25: =COUNTIF($M$19:$M$19,">"&$F25) -> 0
A26: =IF(ISTEXT(F26),"Закрыто",A25+1) -> 7 | B26: =VLOOKUP(RAND(),IAT,3) -> 5 | C26: =B26/1440 -> 0.0034722222 | D26: =VLOOKUP(RAND(),ST,3) -> 8 | E26: =D26/1440 -> 0.0055555556 | F26: =IF(ISTEXT(F25),"",IF(F25+C26>=closed,"Закрыто",F25+C26)) -> 0.39375 | G26: =IF(ISTEXT(F26),"",M26-F26) -> 0 | H26: =IF(ISTEXT(F26),"",IF(G26>(renegat/1440),"Ушел","")) | I26: =IF(H26="Ушел",F26+(renegat/1440),"") | J26: =IF(ISTEXT($F26),"",MAX($P$19:P25,$F26)) -> 0.39513889 | K26: =IF(ISTEXT($F26),"",MAX($R$19:R25,$F26)) -> 0.39583333 | L26: =IF(ISTEXT($F26),"",MAX(T24:T25,$F26)) -> 0.39375 | M26: =IF(ISTEXT(F26),"",MIN(J26:L26)) -> 0.39375 | N26: =IF(OR(ISTEXT(F26),H26="Ушел"),"",MATCH(M26,J26:L26,0)) -> 3 | O26: =IF($N26=1,M26,"") | P26: =IF($N26=1,O26+$E26,P25) -> 0.39513889 | Q26: =IF($N26=2,M26,"") | R26: =IF($N26=2,Q26+$E26,R25) -> 0.39583333 | S26: =IF($N26=3,M26,"") -> 0.39375 | T26: =IF($N26=3,S26+$E26,T25) -> 0.39930556 | U26: =IF(H26="Ушел",I26-F26,G26) -> 0 | V26: =IF(OR(H26="Ушел",A26="Закрыто"),"",E26) -> 0.0055555556 | W26: =IFERROR(Y26-F26,"") -> 0.0055555556 | X26: =IFERROR(IF(H26="Ушел",W26,$E26+G26),"") -> 0.0055555556 | Y26: =IFERROR(IF(H26="Ушел",I26,CHOOSE(N26,P26,R26,T26)),"") -> 0.39930556 | Z26: =COUNTIF($M$19:$M$19,">"&$F26) -> 0
A27: =IF(ISTEXT(F27),"Закрыто",A26+1) -> 8 | B27: =VLOOKUP(RAND(),IAT,3) -> 1 | C27: =B27/1440 -> 0.00069444444 | D27: =VLOOKUP(RAND(),ST,3) -> 3 | E27: =D27/1440 -> 0.0020833333 | F27: =IF(ISTEXT(F26),"",IF(F26+C27>=closed,"Закрыто",F26+C27)) -> 0.39444444 | G27: =IF(ISTEXT(F27),"",M27-F27) -> 0.00069444444 | H27: =IF(ISTEXT(F27),"",IF(G27>(renegat/1440),"Ушел","")) | I27: =IF(H27="Ушел",F27+(renegat/1440),"") | J27: =IF(ISTEXT($F27),"",MAX($P$19:P26,$F27)) -> 0.39513889 | K27: =IF(ISTEXT($F27),"",MAX($R$19:R26,$F27)) -> 0.39583333 | L27: =IF(ISTEXT($F27),"",MAX(T25:T26,$F27)) -> 0.39930556 | M27: =IF(ISTEXT(F27),"",MIN(J27:L27)) -> 0.39513889 | N27: =IF(OR(ISTEXT(F27),H27="Ушел"),"",MATCH(M27,J27:L27,0)) -> 1 | O27: =IF($N27=1,M27,"") -> 0.39513889 | P27: =IF($N27=1,O27+$E27,P26) -> 0.39722222 | Q27: =IF($N27=2,M27,"") | R27: =IF($N27=2,Q27+$E27,R26) -> 0.39583333 | S27: =IF($N27=3,M27,"") | T27: =IF($N27=3,S27+$E27,T26) -> 0.39930556 | U27: =IF(H27="Ушел",I27-F27,G27) -> 0.00069444444 | V27: =IF(OR(H27="Ушел",A27="Закрыто"),"",E27) -> 0.0020833333 | W27: =IFERROR(Y27-F27,"") -> 0.0027777778 | X27: =IFERROR(IF(H27="Ушел",W27,$E27+G27),"") -> 0.0027777778 | Y27: =IFERROR(IF(H27="Ушел",I27,CHOOSE(N27,P27,R27,T27)),"") -> 0.39722222 | Z27: =COUNTIF($M$19:$M$19,">"&$F27) -> 0
A28: =IF(ISTEXT(F28),"Закрыто",A27+1) -> 9 | B28: =VLOOKUP(RAND(),IAT,3) -> 3 | C28: =B28/1440 -> 0.0020833333 | D28: =VLOOKUP(RAND(),ST,3) -> 8 | E28: =D28/1440 -> 0.0055555556 | F28: =IF(ISTEXT(F27),"",IF(F27+C28>=closed,"Закрыто",F27+C28)) -> 0.39652778 | G28: =IF(ISTEXT(F28),"",M28-F28) -> 0 | H28: =IF(ISTEXT(F28),"",IF(G28>(renegat/1440),"Ушел","")) | I28: =IF(H28="Ушел",F28+(renegat/1440),"") | J28: =IF(ISTEXT($F28),"",MAX($P$19:P27,$F28)) -> 0.39722222 | K28: =IF(ISTEXT($F28),"",MAX($R$19:R27,$F28)) -> 0.39652778 | L28: =IF(ISTEXT($F28),"",MAX(T26:T27,$F28)) -> 0.39930556 | M28: =IF(ISTEXT(F28),"",MIN(J28:L28)) -> 0.39652778 | N28: =IF(OR(ISTEXT(F28),H28="Ушел"),"",MATCH(M28,J28:L28,0)) -> 2 | O28: =IF($N28=1,M28,"") | P28: =IF($N28=1,O28+$E28,P27) -> 0.39722222 | Q28: =IF($N28=2,M28,"") -> 0.39652778 | R28: =IF($N28=2,Q28+$E28,R27) -> 0.40208333 | S28: =IF($N28=3,M28,"") | T28: =IF($N28=3,S28+$E28,T27) -> 0.39930556 | U28: =IF(H28="Ушел",I28-F28,G28) -> 0 | V28: =IF(OR(H28="Ушел",A28="Закрыто"),"",E28) -> 0.0055555556 | W28: =IFERROR(Y28-F28,"") -> 0.0055555556 | X28: =IFERROR(IF(H28="Ушел",W28,$E28+G28),"") -> 0.0055555556 | Y28: =IFERROR(IF(H28="Ушел",I28,CHOOSE(N28,P28,R28,T28)),"") -> 0.40208333 | Z28: =COUNTIF($M$19:$M$19,">"&$F28) -> 0
A29: =IF(ISTEXT(F29),"Закрыто",A28+1) -> 10 | B29: =VLOOKUP(RAND(),IAT,3) -> 3 | C29: =B29/1440 -> 0.0020833333 | D29: =VLOOKUP(RAND(),ST,3) -> 8 | E29: =D29/1440 -> 0.0055555556 | F29: =IF(ISTEXT(F28),"",IF(F28+C29>=closed,"Закрыто",F28+C29)) -> 0.39861111 | G29: =IF(ISTEXT(F29),"",M29-F29) -> 0 | H29: =IF(ISTEXT(F29),"",IF(G29>(renegat/1440),"Ушел","")) | I29: =IF(H29="Ушел",F29+(renegat/1440),"") | J29: =IF(ISTEXT($F29),"",MAX($P$19:P28,$F29)) -> 0.39861111 | K29: =IF(ISTEXT($F29),"",MAX($R$19:R28,$F29)) -> 0.40208333 | L29: =IF(ISTEXT($F29),"",MAX(T27:T28,$F29)) -> 0.39930556 | M29: =IF(ISTEXT(F29),"",MIN(J29:L29)) -> 0.39861111 | N29: =IF(OR(ISTEXT(F29),H29="Ушел"),"",MATCH(M29,J29:L29,0)) -> 1 | O29: =IF($N29=1,M29,"") -> 0.39861111 | P29: =IF($N29=1,O29+$E29,P28) -> 0.40416667 | Q29: =IF($N29=2,M29,"") | R29: =IF($N29=2,Q29+$E29,R28) -> 0.40208333 | S29: =IF($N29=3,M29,"") | T29: =IF($N29=3,S29+$E29,T28) -> 0.39930556 | U29: =IF(H29="Ушел",I29-F29,G29) -> 0 | V29: =IF(OR(H29="Ушел",A29="Закрыто"),"",E29) -> 0.0055555556 | W29: =IFERROR(Y29-F29,"") -> 0.0055555556 | X29: =IFERROR(IF(H29="Ушел",W29,$E29+G29),"") -> 0.0055555556 | Y29: =IFERROR(IF(H29="Ушел",I29,CHOOSE(N29,P29,R29,T29)),"") -> 0.40416667 | Z29: =COUNTIF($M$19:$M$19,">"&$F29) -> 0
A30: =IF(ISTEXT(F30),"Закрыто",A29+1) -> 11 | B30: =VLOOKUP(RAND(),IAT,3) -> 3 | C30: =B30/1440 -> 0.0020833333 | D30: =VLOOKUP(RAND(),ST,3) -> 8 | E30: =D30/1440 -> 0.0055555556 | F30: =IF(ISTEXT(F29),"",IF(F29+C30>=closed,"Закрыто",F29+C30)) -> 0.40069444 | G30: =IF(ISTEXT(F30),"",M30-F30) -> 0 | H30: =IF(ISTEXT(F30),"",IF(G30>(renegat/1440),"Ушел","")) | I30: =IF(H30="Ушел",F30+(renegat/1440),"") | J30: =IF(ISTEXT($F30),"",MAX($P$19:P29,$F30)) -> 0.40416667 | K30: =IF(ISTEXT($F30),"",MAX($R$19:R29,$F30)) -> 0.40208333 | L30: =IF(ISTEXT($F30),"",MAX(T28:T29,$F30)) -> 0.40069444 | M30: =IF(ISTEXT(F30),"",MIN(J30:L30)) -> 0.40069444 | N30: =IF(OR(ISTEXT(F30),H30="Ушел"),"",MATCH(M30,J30:L30,0)) -> 3 | O30: =IF($N30=1,M30,"") | P30: =IF($N30=1,O30+$E30,P29) -> 0.40416667 | Q30: =IF($N30=2,M30,"") | R30: =IF($N30=2,Q30+$E30,R29) -> 0.40208333 | S30: =IF($N30=3,M30,"") -> 0.40069444 | T30: =IF($N30=3,S30+$E30,T29) -> 0.40625 | U30: =IF(H30="Ушел",I30-F30,G30) -> 0 | V30: =IF(OR(H30="Ушел",A30="Закрыто"),"",E30) -> 0.0055555556 | W30: =IFERROR(Y30-F30,"") -> 0.0055555556 | X30: =IFERROR(IF(H30="Ушел",W30,$E30+G30),"") -> 0.0055555556 | Y30: =IFERROR(IF(H30="Ушел",I30,CHOOSE(N30,P30,R30,T30)),"") -> 0.40625 | Z30: =COUNTIF($M$19:$M$19,">"&$F30) -> 0
A31: =IF(ISTEXT(F31),"Закрыто",A30+1) -> 12 | B31: =VLOOKUP(RAND(),IAT,3) -> 1 | C31: =B31/1440 -> 0.00069444444 | D31: =VLOOKUP(RAND(),ST,3) -> 7 | E31: =D31/1440 -> 0.0048611111 | F31: =IF(ISTEXT(F30),"",IF(F30+C31>=closed,"Закрыто",F30+C31)) -> 0.40138889 | G31: =IF(ISTEXT(F31),"",M31-F31) -> 0.00069444444 | H31: =IF(ISTEXT(F31),"",IF(G31>(renegat/1440),"Ушел","")) | I31: =IF(H31="Ушел",F31+(renegat/1440),"") | J31: =IF(ISTEXT($F31),"",MAX($P$19:P30,$F31)) -> 0.40416667 | K31: =IF(ISTEXT($F31),"",MAX($R$19:R30,$F31)) -> 0.40208333 | L31: =IF(ISTEXT($F31),"",MAX(T29:T30,$F31)) -> 0.40625 | M31: =IF(ISTEXT(F31),"",MIN(J31:L31)) -> 0.40208333 | N31: =IF(OR(ISTEXT(F31),H31="Ушел"),"",MATCH(M31,J31:L31,0)) -> 2 | O31: =IF($N31=1,M31,"") | P31: =IF($N31=1,O31+$E31,P30) -> 0.40416667 | Q31: =IF($N31=2,M31,"") -> 0.40208333 | R31: =IF($N31=2,Q31+$E31,R30) -> 0.40694444 | S31: =IF($N31=3,M31,"") | T31: =IF($N31=3,S31+$E31,T30) -> 0.40625 | U31: =IF(H31="Ушел",I31-F31,G31) -> 0.00069444444 | V31: =IF(OR(H31="Ушел",A31="Закрыто"),"",E31) -> 0.0048611111 | W31: =IFERROR(Y31-F31,"") -> 0.0055555556 | X31: =IFERROR(IF(H31="Ушел",W31,$E31+G31),"") -> 0.0055555556 | Y31: =IFERROR(IF(H31="Ушел",I31,CHOOSE(N31,P31,R31,T31)),"") -> 0.40694444 | Z31: =COUNTIF($M$19:$M$19,">"&$F31) -> 0
A32: =IF(ISTEXT(F32),"Закрыто",A31+1) -> 13 | B32: =VLOOKUP(RAND(),IAT,3) -> 3 | C32: =B32/1440 -> 0.0020833333 | D32: =VLOOKUP(RAND(),ST,3) -> 8 | E32: =D32/1440 -> 0.0055555556 | F32: =IF(ISTEXT(F31),"",IF(F31+C32>=closed,"Закрыто",F31+C32)) -> 0.40347222 | G32: =IF(ISTEXT(F32),"",M32-F32) -> 0.00069444444 | H32: =IF(ISTEXT(F32),"",IF(G32>(renegat/1440),"Ушел","")) | I32: =IF(H32="Ушел",F32+(renegat/1440),"") | J32: =IF(ISTEXT($F32),"",MAX($P$19:P31,$F32)) -> 0.40416667 | K32: =IF(ISTEXT($F32),"",MAX($R$19:R31,$F32)) -> 0.40694444 | L32: =IF(ISTEXT($F32),"",MAX(T30:T31,$F32)) -> 0.40625 | M32: =IF(ISTEXT(F32),"",MIN(J32:L32)) -> 0.40416667 | N32: =IF(OR(ISTEXT(F32),H32="Ушел"),"",MATCH(M32,J32:L32,0)) -> 1 | O32: =IF($N32=1,M32,"") -> 0.40416667 | P32: =IF($N32=1,O32+$E32,P31) -> 0.40972222 | Q32: =IF($N32=2,M32,"") | R32: =IF($N32=2,Q32+$E32,R31) -> 0.40694444 | S32: =IF($N32=3,M32,"") | T32: =IF($N32=3,S32+$E32,T31) -> 0.40625 | U32: =IF(H32="Ушел",I32-F32,G32) -> 0.00069444444 | V32: =IF(OR(H32="Ушел",A32="Закрыто"),"",E32) -> 0.0055555556 | W32: =IFERROR(Y32-F32,"") -> 0.00625 | X32: =IFERROR(IF(H32="Ушел",W32,$E32+G32),"") -> 0.00625 | Y32: =IFERROR(IF(H32="Ушел",I32,CHOOSE(N32,P32,R32,T32)),"") -> 0.40972222 | Z32: =COUNTIF($M$19:$M$19,">"&$F32) -> 0
... A119: =IF(ISTEXT(F119),"Закрыто",A118+1) -> 100 | B119: =VLOOKUP(RAND(),IAT,3) -> 3 | C119: =B119/1440 -> 0.0020833333 | D119: =VLOOKUP(RAND(),ST,3) -> 8 | E119: =D119/1440 -> 0.0055555556 | F119: =IF(ISTEXT(F118),"",IF(F118+C119>=closed,"Закрыто",F118+C119)) -> 0.62083333 | G119: =IF(ISTEXT(F119),"",M119-F119) -> 0 | H119: =IF(ISTEXT(F119),"",IF(G119>(renegat/1440),"Ушел","")) | I119: =IF(H119="Ушел",F119+(renegat/1440),"") | J119: =IF(ISTEXT($F119),"",MAX($P$19:P118,$F119)) -> 0.62430556 | K119: =IF(ISTEXT($F119),"",MAX($R$19:R118,$F119)) -> 0.62083333 | L119: =IF(ISTEXT($F119),"",MAX(T117:T118,$F119)) -> 0.62083333 | M119: =IF(ISTEXT(F119),"",MIN(J119:L119)) -> 0.62083333 | N119: =IF(OR(ISTEXT(F119),H119="Ушел"),"",MATCH(M119,J119:L119,0)) -> 2 | O119: =IF($N119=1,M119,"") | P119: =IF($N119=1,O119+$E119,P118) -> 0.62430556 | Q119: =IF($N119=2,M119,"") -> 0.62083333 | R119: =IF($N119=2,Q119+$E119,R118) -> 0.62638889 | S119: =IF($N119=3,M119,"") | T119: =IF($N119=3,S119+$E119,T118) -> 0.59861111 | U119: =IF(H119="Ушел",I119-F119,G119) -> 0 | V119: =IF(OR(H119="Ушел",A119="Закрыто"),"",E119) -> 0.0055555556 | W119: =IFERROR(Y119-F119,"") -> 0.0055555556 | X119: =IFERROR(IF(H119="Ушел",W119,$E119+G119),"") -> 0.0055555556 | Y119: =IFERROR(IF(H119="Ушел",I119,CHOOSE(N119,P119,R119,T119)),"") -> 0.62638889 | Z119: =COUNTIF($M$19:$M$19,">"&$F119) -> 0

Sheet эксперимент
B1: Эксперимент1 по модели с 3 серверами и 1 очередью (100)
B2: Счетчик прогонов: | C2: 20
A3: № эксперимента | B3: Среднее время пребывания в системе | C3: Среднее время обслуживания | D3: Количество потерянных заявок на обслуживание | E3: Коэффициент полезной загрузки сервера 1 | F3: Коэффициент полезной загрузки сервера 2 | G3: Коэффициент полезной загрузки сервера 3 | H3: Максимальный размер очереди | I3: Длительность обслуживания клиентов
A4: 1 | B4: =IF(RUNC=A4,ALT,B4) -> 0.0045 | C4: =IF(RUNC=A4,AST,C4) -> 0.0044027778 | D4: =IF(RUNC=A4,NLC,D4) -> 7 | E4: =IF(RUNC=A4,E1F,E4) -> 0.50185185 | F4: =IF(RUNC=A4,E2F,F4) -> 0.58703704 | G4: =IF(RUNC=A4,E3F,G4) -> 0.73703704 | H4: =IF(RUNC=A4,MXQ,H4) -> 0 | I4: =IF(RUNC=A4,MAX(модель!$O$119:$T$119)-[0]!start,I4) -> 0.25902778
A5: 2 | B5: =IF(RUNC=A5,ALT,B5) -> 0.0042083333 | C5: =IF(RUNC=A5,AST,C5) -> 0.0040694444 | D5: =IF(RUNC=A5,NLC,D5) -> 10 | E5: =IF(RUNC=A5,E1F,E5) -> 0.51481481 | F5: =IF(RUNC=A5,E2F,F5) -> 0.64074074 | G5: =IF(RUNC=A5,E3F,G5) -> 0.75925926 | H5: =IF(RUNC=A5,MXQ,H5) -> 0 | I5: =IF(RUNC=A5,MAX(модель!$O$119:$T$119)-[0]!start,I5) -> 0.24027778
A6: 3 | B6: =IF(RUNC=A6,ALT,B6) -> 0.0042777778 | C6: =IF(RUNC=A6,AST,C6) -> 0.0041111111 | D6: =IF(RUNC=A6,NLC,D6) -> 12 | E6: =IF(RUNC=A6,E1F,E6) -> 0.5462963 | F6: =IF(RUNC=A6,E2F,F6) -> 0.63148148 | G6: =IF(RUNC=A6,E3F,G6) -> 0.72592593 | H6: =IF(RUNC=A6,MXQ,H6) -> 0 | I6: =IF(RUNC=A6,MAX(модель!$O$119:$T$119)-[0]!start,I6) -> 0.22916667
A7: 4 | B7: =IF(RUNC=A7,ALT,B7) -> 0.0040763889 | C7: =IF(RUNC=A7,AST,C7) -> 0.0039930556 | D7: =IF(RUNC=A7,NLC,D7) -> 6 | E7: =IF(RUNC=A7,E1F,E7) -> 0.47962963 | F7: =IF(RUNC=A7,E2F,F7) -> 0.65925926 | G7: =IF(RUNC=A7,E3F,G7) -> 0.7962963 | H7: =IF(RUNC=A7,MXQ,H7) -> 0 | I7: =IF(RUNC=A7,MAX(модель!$O$119:$T$119)-[0]!start,I7) -> 0.27361111
A8: 5 | B8: =IF(RUNC=A8,ALT,B8) -> 0.0044166667 | C8: =IF(RUNC=A8,AST,C8) -> 0.0043472222 | D8: =IF(RUNC=A8,NLC,D8) -> 5 | E8: =IF(RUNC=A8,E1F,E8) -> 0.52222222 | F8: =IF(RUNC=A8,E2F,F8) -> 0.59074074 | G8: =IF(RUNC=A8,E3F,G8) -> 0.72777778 | H8: =IF(RUNC=A8,MXQ,H8) -> 0 | I8: =IF(RUNC=A8,MAX(модель!$O$119:$T$119)-[0]!start,I8) -> 0.26180556
A9: 6 | B9: =IF(RUNC=A9,ALT,B9) -> 0.0041319444 | C9: =IF(RUNC=A9,AST,C9) -> 0.0040763889 | D9: =IF(RUNC=A9,NLC,D9) -> 4 | E9: =IF(RUNC=A9,E1F,E9) -> 0.53333333 | F9: =IF(RUNC=A9,E2F,F9) -> 0.64814815 | G9: =IF(RUNC=A9,E3F,G9) -> 0.73148148 | H9: =IF(RUNC=A9,MXQ,H9) -> 0 | I9: =IF(RUNC=A9,MAX(модель!$O$119:$T$119)-[0]!start,I9) -> 0.26805556
A10: 7 | B10: =IF(RUNC=A10,ALT,B10) -> 0.0039027778 | C10: =IF(RUNC=A10,AST,C10) -> 0.0038055556 | D10: =IF(RUNC=A10,NLC,D10) -> 7 | E10: =IF(RUNC=A10,E1F,E10) -> 0.5537037 | F10: =IF(RUNC=A10,E2F,F10) -> 0.63518519 | G10: =IF(RUNC=A10,E3F,G10) -> 0.7962963 | H10: =IF(RUNC=A10,MXQ,H10) -> 0 | I10: =IF(RUNC=A10,MAX(модель!$O$119:$T$119)-[0]!start,I10) -> 0.26180556
A11: 8 | B11: =IF(RUNC=A11,ALT,B11) -> 0.0042083333 | C11: =IF(RUNC=A11,AST,C11) -> 0.0040972222 | D11: =IF(RUNC=A11,NLC,D11) -> 8 | E11: =IF(RUNC=A11,E1F,E11) -> 0.51296296 | F11: =IF(RUNC=A11,E2F,F11) -> 0.63333333 | G11: =IF(RUNC=A11,E3F,G11) -> 0.76111111 | H11: =IF(RUNC=A11,MXQ,H11) -> 0 | I11: =IF(RUNC=A11,MAX(модель!$O$119:$T$119)-[0]!start,I11) -> 0.23263889
A12: 9 | B12: =IF(RUNC=A12,ALT,B12) -> 0.0043819444 | C12: =IF(RUNC=A12,AST,C12) -> 0.0042847222 | D12: =IF(RUNC=A12,NLC,D12) -> 7 | E12: =IF(RUNC=A12,E1F,E12) -> 0.47592593 | F12: =IF(RUNC=A12,E2F,F12) -> 0.61666667 | G12: =IF(RUNC=A12,E3F,G12) -> 0.76481481 | H12: =IF(RUNC=A12,MXQ,H12) -> 0 | I12: =IF(RUNC=A12,MAX(модель!$O$119:$T$119)-[0]!start,I12) -> 0.27638889
A13: 10 | B13: =IF(RUNC=A13,ALT,B13) -> 0.0042986111 | C13: =IF(RUNC=A13,AST,C13) -> 0.0041597222 | D13: =IF(RUNC=A13,NLC,D13) -> 10 | E13: =IF(RUNC=A13,E1F,E13) -> 0.5 | F13: =IF(RUNC=A13,E2F,F13) -> 0.67037037 | G13: =IF(RUNC=A13,E3F,G13) -> 0.72037037 | H13: =IF(RUNC=A13,MXQ,H13) -> 0 | I13: =IF(RUNC=A13,MAX(модель!$O$119:$T$119)-[0]!start,I13) -> 0.24236111
A14: 11 | B14: =IF(RUNC=A14,ALT,B14) -> 0.0043333333 | C14: =IF(RUNC=A14,AST,C14) -> 0.0042083333 | D14: =IF(RUNC=A14,NLC,D14) -> 9 | E14: =IF(RUNC=A14,E1F,E14) -> 0.51666667 | F14: =IF(RUNC=A14,E2F,F14) -> 0.63333333 | G14: =IF(RUNC=A14,E3F,G14) -> 0.72777778 | H14: =IF(RUNC=A14,MXQ,H14) -> 0 | I14: =IF(RUNC=A14,MAX(модель!$O$119:$T$119)-[0]!start,I14) -> 0.225
A15: 12 | B15: =IF(RUNC=A15,ALT,B15) -> 0.0041805556 | C15: =IF(RUNC=A15,AST,C15) -> 0.0041388889 | D15: =IF(RUNC=A15,NLC,D15) -> 3 | E15: =IF(RUNC=A15,E1F,E15) -> 0.46666667 | F15: =IF(RUNC=A15,E2F,F15) -> 0.65925926 | G15: =IF(RUNC=A15,E3F,G15) -> 0.77037037 | H15: =IF(RUNC=A15,MXQ,H15) -> 0 | I15: =IF(RUNC=A15,MAX(модель!$O$119:$T$119)-[0]!start,I15) -> 0.26944444
... A23: 20 | B23: =IF(RUNC=A23,ALT,B23) -> 0.004375 | C23: =IF(RUNC=A23,AST,C23) -> 0.0042916667 | D23: =IF(RUNC=A23,NLC,D23) -> 6 | E23: =IF(RUNC=A23,E1F,E23) -> 0.51111111 | F23: =IF(RUNC=A23,E2F,F23) -> 0.58888889 | G23: =IF(RUNC=A23,E3F,G23) -> 0.75555556 | H23: =IF(RUNC=A23,MXQ,H23) -> 0 | I23: =IF(RUNC=A23,MAX(модель!$O$119:$T$119)-[0]!start,I23) -> 0.25138889
N25: =(Q39-Q38)/7 -> 8.3333333e-05
A26: № эксперимента | B26: Среднее время пребывания в системе | C26: Среднее время обслуживания | D26: Количество потерянных заявок на обслуживание | E26: Коэффициент полезной загрузки сервера 1 | F26: Коэффициент полезной загрузки сервера 2 | G26: Коэффициент полезной загрузки сервера 3 | H26: Максимальный размер очереди | I26: Длительность обслуживания клиентов
A27: 1 | B27: 0.0041319444 | C27: 0.0040902778 | D27: 3 | E27: 0.46851852 | F27: 0.64814815 | G27: 0.79259259 | H27: 0 | I27: 0.29166667 | K27: =Q38 -> 0.0039722222 | P27: Среднее время пребывания | T27: Коэффициент полезной загрузки сервера 1
A28: 2 | B28: 0.0043402778 | C28: 0.0042152778 | D28: 9 | E28: 0.50555556 | F28: 0.63333333 | G28: 0.73703704 | H28: 0 | I28: 0.24513889 | K28: =K27+$N$25 -> 0.0040555556 | X28: 1 | Y28: 2 | Z28: 3
A29: 3 | B29: 0.0043263889 | C29: 0.0041458333 | D29: 13 | E29: 0.51296296 | F29: 0.63333333 | G29: 0.74814815 | H29: 0 | I29: 0.24583333 | K29: =K28+$N$25 -> 0.0041388889 | P29: Среднее | Q29: 0.0042670139 | T29: Среднее | U29: 0.48953704 | W29: Максимум | X29: =U39 -> 0.54259259 | Y29: =U55 -> 0.67592593 | Z29: =U71 -> 0.82037037
A30: 4 | B30: 0.0043819444 | C30: 0.0043125 | D30: 5 | E30: 0.46111111 | F30: 0.64259259 | G30: 0.7462963 | H30: 0 | I30: 0.30972222 | K30: =K29+$N$25 -> 0.0042222222 | P30: Стандартная ошибка | Q30: 3.474588e-05 | T30: Стандартная ошибка | U30: 0.0064532594 | W30: Минимум | X30: =U38 -> 0.42407407 | Y30: =U54 -> 0.5962963 | Z30: =U70 -> 0.72777778
A31: 5 | B31: 0.0042847222 | C31: 0.0041597222 | D31: 9 | E31: 0.48518519 | F31: 0.67222222 | G31: 0.73333333 | H31: 0 | I31: 0.25347222 | K31: =K30+$N$25 -> 0.0043055556 | P31: Медиана | Q31: 0.0042743056 | T31: Медиана | U31: 0.49166667 | W31: Среднее | X31: =U29 -> 0.48953704 | Y31: =U45 -> 0.63712963 | Z31: =U61 -> 0.7612037
A32: 6 | B32: 0.0041666667 | C32: 0.0040833333 | D32: 6 | E32: 0.51851852 | F32: 0.65 | G32: 0.74259259 | H32: 0 | I32: 0.22916667 | K32: =K31+$N$25 -> 0.0043888889 | P32: Мода | Q32: 0.0043263889 | T32: Мода | U32: 0.51296296
A33: 7 | B33: 0.0042638889 | C33: 0.0041111111 | D33: 11 | E33: 0.51851852 | F33: 0.6462963 | G33: 0.73888889 | H33: 0 | I33: 0.22430556 | K33: =K32+$N$25 -> 0.0044722222 | P33: Стандартное отклонение | Q33: 0.0001553883 | T33: Стандартное отклонение | U33: 0.028859853
A34: 8 | B34: 0.0045069444 | C34: 0.0043958333 | D34: 8 | E34: 0.45555556 | F34: 0.61481481 | G34: 0.75740741 | H34: 0 | I34: 0.29027778 | K34: =K33+$N$25 -> 0.0045555556 | P34: Дисперсия выборки | Q34: 2.4145524e-08 | T34: Дисперсия выборки | U34: 0.00083289113
A35: 9 | B35: 0.0041875 | C35: 0.0040902778 | D35: 7 | E35: 0.51666667 | F35: 0.63333333 | G35: 0.75925926 | H35: 0 | I35: 0.25416667 | P35: Эксцесс | Q35: -0.13765078 | T35: Эксцесс | U35: -0.061460261
A36: 10 | B36: 0.0039791667 | C36: 0.0038125 | D36: 12 | E36: 0.51296296 | F36: 0.67592593 | G36: 0.79444444 | H36: 0 | I36: 0.27291667 | P36: Асимметричность | Q36: -0.13521244 | T36: Асимметричность | U36: -0.39394141
A37: 11 | B37: 0.0045555556 | C37: 0.0044722222 | D37: 6 | E37: 0.46296296 | F37: 0.59814815 | G37: 0.7462963 | H37: 0 | I37: 0.28055556 | P37: Интервал | Q37: 0.00058333333 | T37: Интервал | U37: 0.11851852
A38: 12 | B38: 0.0041666667 | C38: 0.0040555556 | D38: 8 | E38: 0.49444444 | F38: 0.64444444 | G38: 0.77962963 | H38: 0 | I38: 0.26458333 | P38: Минимум | Q38: 0.0039722222 | T38: Минимум | U38: 0.42407407
A39: 13 | B39: 0.0043263889 | C39: 0.0042708333 | D39: 4 | E39: 0.4537037 | F39: 0.66111111 | G39: 0.7462963 | H39: 0 | I39: 0.29305556 | P39: Максимум | Q39: 0.0045555556 | T39: Максимум | U39: 0.54259259
A40: 14 | B40: 0.0042430556 | C40: 0.0041319444 | D40: 8 | E40: 0.48148148 | F40: 0.5962963 | G40: 0.82037037 | H40: 0 | I40: 0.28541667 | P40: Сумма | Q40: 0.085340278 | T40: Сумма | U40: 9.7907407
A41: 15 | B41: 0.0042430556 | C41: 0.0041736111 | D41: 5 | E41: 0.49444444 | F41: 0.63888889 | G41: 0.7537037 | H41: 0 | I41: 0.28680556 | P41: Счет | Q41: 20 | T41: Счет | U41: 20
A42: 16 | B42: 0.0041180556 | C42: 0.0039791667 | D42: 10 | E42: 0.54259259 | F42: 0.64074074 | G42: 0.75555556 | H42: 0 | I42: 0.22777778
A43: 17 | B43: 0.0042847222 | C43: 0.0042013889 | D43: 6 | E43: 0.48888889 | F43: 0.62777778 | G43: 0.76296296 | H43: 0 | I43: 0.27708333 | P43: Среднее время обслуживания | T43: Коэффициент полезной загрузки сервера 2
A44: 18 | B44: 0.0044166667 | C44: 0.0043333333 | D44: 6 | E44: 0.48333333 | F44: 0.63333333 | G44: 0.72777778 | H44: 0 | I44: 0.22847222
A45: 19 | B45: 0.0039722222 | C45: 0.0039444444 | D45: 2 | E45: 0.50925926 | F45: 0.64259259 | G45: 0.7962963 | H45: 0 | I45: 0.2875 | P45: Среднее | Q45: 0.0041704861 | T45: Среднее | U45: 0.63712963
A46: 20 | B46: 0.0044444444 | C46: 0.0044305556 | D46: 1 | E46: 0.42407407 | F46: 0.60925926 | G46: 0.78518519 | H46: 0 | I46: 0.30069444 | P46: Стандартная ошибка | Q46: 3.7150045e-05 | T46: Стандартная ошибка | U46: 0.0047069086
A47: Итог | B47: =SUBTOTAL(101,Таблица1[Среднее время пребывания в системе]) -> 0.0042670139 | C47: =SUBTOTAL(101,Таблица1[Среднее время обслуживания]) -> 0.0041704861 | D47: =SUBTOTAL(104,Таблица1[Количество потерянных заявок на обслуживание]) -> 13 | E47: =SUBTOTAL(101,Таблица1[Коэффициент полезной загрузки сервера 1]) -> 0.48953704 | F47: =SUBTOTAL(101,Таблица1[Коэффициент полезной загрузки сервера 2]) -> 0.63712963 | G47: =SUBTOTAL(101,Таблица1[Коэффициент полезной загрузки сервера 3]) -> 0.7612037 | H47: =SUBTOTAL(105,Таблица1[Максимальный размер очереди]) -> 0 | I47: =SUBTOTAL(104,Таблица1[Длительность обслуживания клиентов]) -> 0.30972222 | P47: Медиана | Q47: 0.0041527778 | T47: Медиана | U47: 0.63981481
P48: Мода | Q48: #N/A | T48: Мода | U48: 0.63333333
...

Sheet пример
